<?xml version="1.0" ?>
<!-- =================================================================================== -->
<!-- |    This document was autogenerated by xacro from robot_core.xacro               | -->
<!-- |    EDITING THIS FILE BY HAND IS NOT RECOMMENDED                                 | -->
<!-- =================================================================================== -->
<robot name="pinky">
  <!-- Specify some standard inertial calculations https://en.wikipedia.org/wiki/List_of_moments_of_inertia -->
  <!-- These make use of xacro's mathematical functionality -->
  <material name="white">
    <color rgba="1 1 1 1"/>
  </material>
  <link name="base_footprint"/>
  <joint name="base_link_fixed_joint" type="fixed">
    <parent link="base_footprint"/>
    <child link="base_link"/>
    <origin rpy="0 0 0" xyz="0 0 0.03"/>
  </joint>
  <link name="base_link"/>
  <joint name="chassis_fixed_joint" type="fixed">
    <parent link="base_link"/>
    <child link="chassis"/>
    <origin rpy="0 0 0" xyz="0 0 0"/>
  </joint>
  <link name="chassis">
    <visual>
      <origin rpy="0 0 0" xyz="0 0 0"/>
      <geometry>
        <mesh filename="package://pinky_description/meshes/visual/base_link.dae" scale="1 1 1"/>
      </geometry>
    </visual>
    <collision>
      <origin rpy="0 0 0" xyz="-0.01 0 0.01"/>
      <geometry>
        <box size="0.1 0.08 0.06"/>
      </geometry>
    </collision>
    <inertial>
      <origin rpy="0 0 0" xyz="-0.01 0 0.01"/>
      <mass value="1.0"/>
      <inertia ixx="0.0008333333333333333" ixy="0.0" ixz="0.0" iyy="0.0011333333333333334" iyz="0.0" izz="0.0013666666666666666"/>
    </inertial>
  </link>
  <joint name="caster_fixed_joint" type="fixed">
    <parent link="chassis"/>
    <child link="caster"/>
    <origin rpy="0 0 0" xyz="-0.044 0 -0.02"/>
  </joint>
  <link name="caster">
    <visual>
      <origin rpy="0 0 0" xyz="0 0 0"/>
      <geometry>
        <sphere radius="0.01"/>
      </geometry>
      <material name="white"/>
    </visual>
    <collision>
      <origin rpy="0 0 0" xyz="0 0 0"/>
      <geometry>
        <sphere radius="0.01"/>
      </geometry>
    </collision>
    <inertial>
      <origin rpy="0 0 0" xyz="0 0 0"/>
      <mass value="0.7"/>
      <inertia ixx="2.8e-05" ixy="0.0" ixz="0.0" iyy="2.8e-05" iyz="0.0" izz="2.8e-05"/>
    </inertial>
  </link>
  <joint name="left_wheel_joint" type="continuous">
    <parent link="base_link"/>
    <child link="left_wheel"/>
    <origin rpy="-1.5707963267948966 0 0" xyz="0 0.055 0"/>
    <axis xyz="0 0 1"/>
  </joint>
  <link name="left_wheel">
    <visual>
      <origin rpy="0 0 0" xyz="0 0 0"/>
      <geometry>
        <mesh filename="package://pinky_description/meshes/visual/wheel.dae" scale="1 1 1"/>
      </geometry>
    </visual>
    <collision>
      <origin rpy="0 0 0" xyz="0 0 0"/>
      <geometry>
        <cylinder length="0.014" radius="0.03"/>
      </geometry>
    </collision>
    <inertial>
      <origin rpy="0 0 0" xyz="0 0 0"/>
      <mass value="0.05"/>
      <inertia ixx="1.2066666666666666e-05" ixy="0.0" ixz="0.0" iyy="1.2066666666666666e-05" iyz="0.0" izz="2.25e-05"/>
    </inertial>
  </link>
  <joint name="right_wheel_joint" type="continuous">
    <parent link="base_link"/>
    <child link="right_wheel"/>
    <origin rpy="1.5707963267948966 0 0" xyz="0 -0.055 0"/>
    <axis xyz="0 0 -1"/>
  </joint>
  <link name="right_wheel">
    <visual>
      <origin rpy="0 0 0" xyz="0 0 0"/>
      <geometry>
        <mesh filename="package://pinky_description/meshes/visual/wheel.dae" scale="1 1 1"/>
      </geometry>
    </visual>
    <collision>
      <origin rpy="0 0 0" xyz="0 0 0"/>
      <geometry>
        <cylinder length="0.014" radius="0.03"/>
      </geometry>
    </collision>
    <inertial>
      <origin rpy="0 0 0" xyz="0 0 0"/>
      <mass value="0.05"/>
      <inertia ixx="1.2066666666666666e-05" ixy="0.0" ixz="0.0" iyy="1.2066666666666666e-05" iyz="0.0" izz="2.25e-05"/>
    </inertial>
  </link>
  <link name="ul_sensor_mount">
    <visual>
      <origin rpy="0 0 0" xyz="0 0 0"/>
      <geometry>
        <mesh filename="package://pinky_description/meshes/visual/ul_sensor.dae" scale="1 1 1"/>
      </geometry>
    </visual>
    <collision>
      <origin rpy="0 0 0" xyz="0 0 0"/>
      <geometry>
        <mesh filename="package://pinky_description/meshes/collision/ul_sensor.stl" scale="1 1 1"/>
      </geometry>
    </collision>
    <inertial>
      <origin rpy="0 0 0" xyz="0.005 0 0.013"/>
      <mass value="0.050000"/>
      <inertia ixx="0.000005" ixy="0" ixz="-0.000001" iyy="0.000004" iyz="0" izz="0.000003"/>
    </inertial>
  </link>
  <joint name="ul_sensor_mount_fixed_joint" type="fixed">
    <parent link="chassis"/>
    <child link="ul_sensor_mount"/>
    <origin rpy="0 0 0" xyz="0.038 -0.002 -0.0035"/>
  </joint>
  <link name="ul_sensor_link"/>
  <joint name="ul_sensor_link_fixed_joint" type="fixed">
    <parent link="ul_sensor_mount"/>
    <child link="ul_sensor_link"/>
    <origin rpy="0 0 0" xyz="0.01 0 0"/>
  </joint>
  <link name="front_camera_mount">
    <visual>
      <origin rpy="0 0 0" xyz="0 0 0"/>
      <geometry>
        <mesh filename="package://pinky_description/meshes/visual/camera.dae" scale="1 1 1"/>
      </geometry>
    </visual>
    <collision>
      <origin rpy="0 0 0" xyz="0 0 0"/>
      <geometry>
        <mesh filename="package://pinky_description/meshes/collision/camera.stl" scale="1 1 1"/>
      </geometry>
    </collision>
    <inertial>
      <origin rpy="0 0 0" xyz="0.005 0 0.013"/>
      <mass value="0.050000"/>
      <inertia ixx="0.000005" ixy="0" ixz="-0.000001" iyy="0.000004" iyz="0" izz="0.000003"/>
    </inertial>
  </link>
  <joint name="front_camera_mount_fixed_joint" type="fixed">
    <parent link="chassis"/>
    <child link="front_camera_mount"/>
    <origin rpy="0 0 0" xyz="0.05 -0.001 0.028"/>
  </joint>
  <link name="camera_link"/>
  <joint name="camera_link_fixed_joint" type="fixed">
    <parent link="front_camera_mount"/>
    <child link="camera_link"/>
    <origin rpy="-1.5707963267948966 0 -1.5707963267948966" xyz="0.001 0 0.003"/>
  </joint>
  <link name="lidar_lidar_mount">
    <visual>
      <origin rpy="0 0 0" xyz="0 0 0"/>
      <geometry>
        <mesh filename="package://pinky_description/meshes/visual/lidar.dae" scale="1 1 1"/>
      </geometry>
    </visual>
    <collision>
      <origin rpy="0 0 0" xyz="0 0 0"/>
      <geometry>
        <mesh filename="package://pinky_description/meshes/collision/lidar.stl" scale="1 1 1"/>
      </geometry>
    </collision>
    <inertial>
      <origin rpy="0 0 0" xyz="0.007 0 0.025"/>
      <mass value="0.110"/>
      <inertia ixx="0.000058" ixy="0" ixz="0.000005" iyy="0.000099" iyz="0" izz="0.000103"/>
    </inertial>
  </link>
  <joint name="lidar_mount_fixed_joint" type="fixed">
    <parent link="chassis"/>
    <child link="lidar_lidar_mount"/>
    <origin rpy="0 0 0" xyz="0 0 0.042"/>
  </joint>
  <link name="laser_link"/>
  <joint name="laser_link_fixed_joint" type="fixed">
    <parent link="lidar_lidar_mount"/>
    <child link="laser_link"/>
    <origin rpy="0 0 3.141592653589793" xyz="0.0 0 0.03"/>
  </joint>
  <link name="imu_link"/>
  <joint name="imu_link_joint" type="fixed">
    <parent link="chassis"/>
    <child link="imu_link"/>
    <origin rpy="0 0 0" xyz="0 0 0.03"/>
  </joint>
</robot>
